[2022-07-27 23:22:03,291.291] ERROR [215144] - Exception in ASGI application
Traceback (most recent call last):
  File "C:\Users\soju_\AppData\Local\Programs\Python\Python310\lib\site-packages\uvicorn\protocols\http\httptools_impl.py", line 401, in run_asgi
    result = await app(self.scope, self.receive, self.send)
  File "C:\Users\soju_\AppData\Local\Programs\Python\Python310\lib\site-packages\uvicorn\middleware\proxy_headers.py", line 78, in __call__
    return await self.app(scope, receive, send)
  File "C:\Users\soju_\AppData\Local\Programs\Python\Python310\lib\site-packages\uvicorn\middleware\message_logger.py", line 86, in __call__
    raise exc from None
  File "C:\Users\soju_\AppData\Local\Programs\Python\Python310\lib\site-packages\uvicorn\middleware\message_logger.py", line 82, in __call__
    await self.app(scope, inner_receive, inner_send)
  File "C:\Users\soju_\AppData\Local\Programs\Python\Python310\lib\site-packages\fastapi\applications.py", line 269, in __call__
    await super().__call__(scope, receive, send)
  File "C:\Users\soju_\AppData\Local\Programs\Python\Python310\lib\site-packages\starlette\applications.py", line 124, in __call__
    await self.middleware_stack(scope, receive, send)
  File "C:\Users\soju_\AppData\Local\Programs\Python\Python310\lib\site-packages\starlette\middleware\errors.py", line 184, in __call__
    raise exc
  File "C:\Users\soju_\AppData\Local\Programs\Python\Python310\lib\site-packages\starlette\middleware\errors.py", line 162, in __call__
    await self.app(scope, receive, _send)
  File "C:\Users\soju_\AppData\Local\Programs\Python\Python310\lib\site-packages\starlette\middleware\base.py", line 68, in __call__
    response = await self.dispatch_func(request, call_next)
  File "z:\pl\micro\cdn\middleware\internal_api.py", line 45, in dispatch
    return await next(req)
  File "C:\Users\soju_\AppData\Local\Programs\Python\Python310\lib\site-packages\starlette\middleware\base.py", line 46, in call_next
    raise app_exc
  File "C:\Users\soju_\AppData\Local\Programs\Python\Python310\lib\site-packages\starlette\middleware\base.py", line 36, in coro
    await self.app(scope, request.receive, send_stream.send)
  File "C:\Users\soju_\AppData\Local\Programs\Python\Python310\lib\site-packages\content_size_limit_asgi\middleware.py", line 56, in __call__
    await self.app(scope, wrapper, send)
  File "C:\Users\soju_\AppData\Local\Programs\Python\Python310\lib\site-packages\starlette\exceptions.py", line 93, in __call__
    raise exc
  File "C:\Users\soju_\AppData\Local\Programs\Python\Python310\lib\site-packages\starlette\exceptions.py", line 82, in __call__
    await self.app(scope, receive, sender)
  File "C:\Users\soju_\AppData\Local\Programs\Python\Python310\lib\site-packages\fastapi\middleware\asyncexitstack.py", line 21, in __call__
    raise e
  File "C:\Users\soju_\AppData\Local\Programs\Python\Python310\lib\site-packages\fastapi\middleware\asyncexitstack.py", line 18, in __call__
    await self.app(scope, receive, send)
  File "C:\Users\soju_\AppData\Local\Programs\Python\Python310\lib\site-packages\starlette\routing.py", line 670, in __call__
    await route.handle(scope, receive, send)
  File "C:\Users\soju_\AppData\Local\Programs\Python\Python310\lib\site-packages\starlette\routing.py", line 266, in handle
    await self.app(scope, receive, send)
  File "C:\Users\soju_\AppData\Local\Programs\Python\Python310\lib\site-packages\starlette\routing.py", line 65, in app
    response = await func(request)
  File "C:\Users\soju_\AppData\Local\Programs\Python\Python310\lib\site-packages\fastapi\routing.py", line 227, in app
    raw_response = await run_endpoint_function(
  File "C:\Users\soju_\AppData\Local\Programs\Python\Python310\lib\site-packages\fastapi\routing.py", line 160, in run_endpoint_function
    return await dependant.call(**values)
  File "z:\pl\micro\cdn\routes\internal\cdn.py", line 34, in upload
    access = content.register(
  File "z:\pl\micro\cdn\database\content.py", line 53, in register
    access = create_access()
  File "z:\pl\micro\cdn\database\content.py", line 47, in create_access
    if exists(access, level=None):
  File "z:\pl\micro\cdn\database\content.py", line 27, in exists
    return next(iter(db.fetchone(
  File "z:\pl\micro\cdn\database\db.py", line 35, in fetchone
    cursor.execute(sql, args)
  File "C:\Users\soju_\AppData\Local\Programs\Python\Python310\lib\site-packages\pymysql\cursors.py", line 148, in execute
    result = self._query(query)
  File "C:\Users\soju_\AppData\Local\Programs\Python\Python310\lib\site-packages\pymysql\cursors.py", line 310, in _query
    conn.query(q)
  File "C:\Users\soju_\AppData\Local\Programs\Python\Python310\lib\site-packages\pymysql\connections.py", line 548, in query
    self._affected_rows = self._read_query_result(unbuffered=unbuffered)
  File "C:\Users\soju_\AppData\Local\Programs\Python\Python310\lib\site-packages\pymysql\connections.py", line 775, in _read_query_result
    result.read()
  File "C:\Users\soju_\AppData\Local\Programs\Python\Python310\lib\site-packages\pymysql\connections.py", line 1156, in read
    first_packet = self.connection._read_packet()
  File "C:\Users\soju_\AppData\Local\Programs\Python\Python310\lib\site-packages\pymysql\connections.py", line 725, in _read_packet
    packet.raise_for_error()
  File "C:\Users\soju_\AppData\Local\Programs\Python\Python310\lib\site-packages\pymysql\protocol.py", line 221, in raise_for_error
    err.raise_mysql_exception(self._data)
  File "C:\Users\soju_\AppData\Local\Programs\Python\Python310\lib\site-packages\pymysql\err.py", line 143, in raise_mysql_exception
    raise errorclass(errno, errval)
pymysql.err.ProgrammingError: (1146, "Table 'pl.auth.contents' doesn't exist")
