[2022-07-27 23:22:03,291.291] ERROR [215144] - Exception in ASGI application
Traceback (most recent call last):
  File "C:\Users\soju_\AppData\Local\Programs\Python\Python310\lib\site-packages\uvicorn\protocols\http\httptools_impl.py", line 401, in run_asgi
    result = await app(self.scope, self.receive, self.send)
  File "C:\Users\soju_\AppData\Local\Programs\Python\Python310\lib\site-packages\uvicorn\middleware\proxy_headers.py", line 78, in __call__
    return await self.app(scope, receive, send)
  File "C:\Users\soju_\AppData\Local\Programs\Python\Python310\lib\site-packages\uvicorn\middleware\message_logger.py", line 86, in __call__
    raise exc from None
  File "C:\Users\soju_\AppData\Local\Programs\Python\Python310\lib\site-packages\uvicorn\middleware\message_logger.py", line 82, in __call__
    await self.app(scope, inner_receive, inner_send)
  File "C:\Users\soju_\AppData\Local\Programs\Python\Python310\lib\site-packages\fastapi\applications.py", line 269, in __call__
    await super().__call__(scope, receive, send)
  File "C:\Users\soju_\AppData\Local\Programs\Python\Python310\lib\site-packages\starlette\applications.py", line 124, in __call__
    await self.middleware_stack(scope, receive, send)
  File "C:\Users\soju_\AppData\Local\Programs\Python\Python310\lib\site-packages\starlette\middleware\errors.py", line 184, in __call__
    raise exc
  File "C:\Users\soju_\AppData\Local\Programs\Python\Python310\lib\site-packages\starlette\middleware\errors.py", line 162, in __call__
    await self.app(scope, receive, _send)
  File "C:\Users\soju_\AppData\Local\Programs\Python\Python310\lib\site-packages\starlette\middleware\base.py", line 68, in __call__
    response = await self.dispatch_func(request, call_next)
  File "z:\pl\micro\cdn\middleware\internal_api.py", line 45, in dispatch
    return await next(req)
  File "C:\Users\soju_\AppData\Local\Programs\Python\Python310\lib\site-packages\starlette\middleware\base.py", line 46, in call_next
    raise app_exc
  File "C:\Users\soju_\AppData\Local\Programs\Python\Python310\lib\site-packages\starlette\middleware\base.py", line 36, in coro
    await self.app(scope, request.receive, send_stream.send)
  File "C:\Users\soju_\AppData\Local\Programs\Python\Python310\lib\site-packages\content_size_limit_asgi\middleware.py", line 56, in __call__
    await self.app(scope, wrapper, send)
  File "C:\Users\soju_\AppData\Local\Programs\Python\Python310\lib\site-packages\starlette\exceptions.py", line 93, in __call__
    raise exc
  File "C:\Users\soju_\AppData\Local\Programs\Python\Python310\lib\site-packages\starlette\exceptions.py", line 82, in __call__
    await self.app(scope, receive, sender)
  File "C:\Users\soju_\AppData\Local\Programs\Python\Python310\lib\site-packages\fastapi\middleware\asyncexitstack.py", line 21, in __call__
    raise e
  File "C:\Users\soju_\AppData\Local\Programs\Python\Python310\lib\site-packages\fastapi\middleware\asyncexitstack.py", line 18, in __call__
    await self.app(scope, receive, send)
  File "C:\Users\soju_\AppData\Local\Programs\Python\Python310\lib\site-packages\starlette\routing.py", line 670, in __call__
    await route.handle(scope, receive, send)
  File "C:\Users\soju_\AppData\Local\Programs\Python\Python310\lib\site-packages\starlette\routing.py", line 266, in handle
    await self.app(scope, receive, send)
  File "C:\Users\soju_\AppData\Local\Programs\Python\Python310\lib\site-packages\starlette\routing.py", line 65, in app
    response = await func(request)
  File "C:\Users\soju_\AppData\Local\Programs\Python\Python310\lib\site-packages\fastapi\routing.py", line 227, in app
    raw_response = await run_endpoint_function(
  File "C:\Users\soju_\AppData\Local\Programs\Python\Python310\lib\site-packages\fastapi\routing.py", line 160, in run_endpoint_function
    return await dependant.call(**values)
  File "z:\pl\micro\cdn\routes\internal\cdn.py", line 34, in upload
    access = content.register(
  File "z:\pl\micro\cdn\database\content.py", line 53, in register
    access = create_access()
  File "z:\pl\micro\cdn\database\content.py", line 47, in create_access
    if exists(access, level=None):
  File "z:\pl\micro\cdn\database\content.py", line 27, in exists
    return next(iter(db.fetchone(
  File "z:\pl\micro\cdn\database\db.py", line 35, in fetchone
    cursor.execute(sql, args)
  File "C:\Users\soju_\AppData\Local\Programs\Python\Python310\lib\site-packages\pymysql\cursors.py", line 148, in execute
    result = self._query(query)
  File "C:\Users\soju_\AppData\Local\Programs\Python\Python310\lib\site-packages\pymysql\cursors.py", line 310, in _query
    conn.query(q)
  File "C:\Users\soju_\AppData\Local\Programs\Python\Python310\lib\site-packages\pymysql\connections.py", line 548, in query
    self._affected_rows = self._read_query_result(unbuffered=unbuffered)
  File "C:\Users\soju_\AppData\Local\Programs\Python\Python310\lib\site-packages\pymysql\connections.py", line 775, in _read_query_result
    result.read()
  File "C:\Users\soju_\AppData\Local\Programs\Python\Python310\lib\site-packages\pymysql\connections.py", line 1156, in read
    first_packet = self.connection._read_packet()
  File "C:\Users\soju_\AppData\Local\Programs\Python\Python310\lib\site-packages\pymysql\connections.py", line 725, in _read_packet
    packet.raise_for_error()
  File "C:\Users\soju_\AppData\Local\Programs\Python\Python310\lib\site-packages\pymysql\protocol.py", line 221, in raise_for_error
    err.raise_mysql_exception(self._data)
  File "C:\Users\soju_\AppData\Local\Programs\Python\Python310\lib\site-packages\pymysql\err.py", line 143, in raise_mysql_exception
    raise errorclass(errno, errval)
pymysql.err.ProgrammingError: (1146, "Table 'pl.auth.contents' doesn't exist")
[2022-07-28 16:20:11,662.662] ERROR [232100] - Exception in ASGI application
Traceback (most recent call last):
  File "C:\Users\soju_\AppData\Local\Programs\Python\Python310\lib\site-packages\uvicorn\protocols\http\httptools_impl.py", line 401, in run_asgi
    result = await app(self.scope, self.receive, self.send)
  File "C:\Users\soju_\AppData\Local\Programs\Python\Python310\lib\site-packages\uvicorn\middleware\proxy_headers.py", line 78, in __call__
    return await self.app(scope, receive, send)
  File "C:\Users\soju_\AppData\Local\Programs\Python\Python310\lib\site-packages\uvicorn\middleware\message_logger.py", line 86, in __call__
    raise exc from None
  File "C:\Users\soju_\AppData\Local\Programs\Python\Python310\lib\site-packages\uvicorn\middleware\message_logger.py", line 82, in __call__
    await self.app(scope, inner_receive, inner_send)
  File "C:\Users\soju_\AppData\Local\Programs\Python\Python310\lib\site-packages\fastapi\applications.py", line 269, in __call__
    await super().__call__(scope, receive, send)
  File "C:\Users\soju_\AppData\Local\Programs\Python\Python310\lib\site-packages\starlette\applications.py", line 124, in __call__
    await self.middleware_stack(scope, receive, send)
  File "C:\Users\soju_\AppData\Local\Programs\Python\Python310\lib\site-packages\starlette\middleware\errors.py", line 184, in __call__
    raise exc
  File "C:\Users\soju_\AppData\Local\Programs\Python\Python310\lib\site-packages\starlette\middleware\errors.py", line 162, in __call__
    await self.app(scope, receive, _send)
  File "C:\Users\soju_\AppData\Local\Programs\Python\Python310\lib\site-packages\starlette\middleware\base.py", line 68, in __call__
    response = await self.dispatch_func(request, call_next)
  File "Z:\pl\micro\cdn\.\middleware\internal_api.py", line 34, in dispatch
    return await next(req)
  File "C:\Users\soju_\AppData\Local\Programs\Python\Python310\lib\site-packages\starlette\middleware\base.py", line 46, in call_next
    raise app_exc
  File "C:\Users\soju_\AppData\Local\Programs\Python\Python310\lib\site-packages\starlette\middleware\base.py", line 36, in coro
    await self.app(scope, request.receive, send_stream.send)
  File "C:\Users\soju_\AppData\Local\Programs\Python\Python310\lib\site-packages\content_size_limit_asgi\middleware.py", line 56, in __call__
    await self.app(scope, wrapper, send)
  File "C:\Users\soju_\AppData\Local\Programs\Python\Python310\lib\site-packages\starlette\exceptions.py", line 93, in __call__
    raise exc
  File "C:\Users\soju_\AppData\Local\Programs\Python\Python310\lib\site-packages\starlette\exceptions.py", line 82, in __call__
    await self.app(scope, receive, sender)
  File "C:\Users\soju_\AppData\Local\Programs\Python\Python310\lib\site-packages\fastapi\middleware\asyncexitstack.py", line 21, in __call__
    raise e
  File "C:\Users\soju_\AppData\Local\Programs\Python\Python310\lib\site-packages\fastapi\middleware\asyncexitstack.py", line 18, in __call__
    await self.app(scope, receive, send)
  File "C:\Users\soju_\AppData\Local\Programs\Python\Python310\lib\site-packages\starlette\routing.py", line 670, in __call__
    await route.handle(scope, receive, send)
  File "C:\Users\soju_\AppData\Local\Programs\Python\Python310\lib\site-packages\starlette\routing.py", line 266, in handle
    await self.app(scope, receive, send)
  File "C:\Users\soju_\AppData\Local\Programs\Python\Python310\lib\site-packages\starlette\routing.py", line 65, in app
    response = await func(request)
  File "C:\Users\soju_\AppData\Local\Programs\Python\Python310\lib\site-packages\fastapi\routing.py", line 227, in app
    raw_response = await run_endpoint_function(
  File "C:\Users\soju_\AppData\Local\Programs\Python\Python310\lib\site-packages\fastapi\routing.py", line 160, in run_endpoint_function
    return await dependant.call(**values)
  File "Z:\pl\micro\cdn\.\routes\get.py", line 25, in get
    content = sess.query(Content).filter(Content.access == access_id).first()
  File "C:\Users\soju_\AppData\Local\Programs\Python\Python310\lib\site-packages\sqlalchemy\orm\query.py", line 2819, in first
    return self.limit(1)._iter().first()
  File "C:\Users\soju_\AppData\Local\Programs\Python\Python310\lib\site-packages\sqlalchemy\orm\query.py", line 2903, in _iter
    result = self.session.execute(
  File "C:\Users\soju_\AppData\Local\Programs\Python\Python310\lib\site-packages\sqlalchemy\orm\session.py", line 1712, in execute
    result = conn._execute_20(statement, params or {}, execution_options)
  File "C:\Users\soju_\AppData\Local\Programs\Python\Python310\lib\site-packages\sqlalchemy\engine\base.py", line 1631, in _execute_20
    return meth(self, args_10style, kwargs_10style, execution_options)
  File "C:\Users\soju_\AppData\Local\Programs\Python\Python310\lib\site-packages\sqlalchemy\sql\elements.py", line 332, in _execute_on_connection
    return connection._execute_clauseelement(
  File "C:\Users\soju_\AppData\Local\Programs\Python\Python310\lib\site-packages\sqlalchemy\engine\base.py", line 1498, in _execute_clauseelement
    ret = self._execute_context(
  File "C:\Users\soju_\AppData\Local\Programs\Python\Python310\lib\site-packages\sqlalchemy\engine\base.py", line 1862, in _execute_context
    self._handle_dbapi_exception(
  File "C:\Users\soju_\AppData\Local\Programs\Python\Python310\lib\site-packages\sqlalchemy\engine\base.py", line 2043, in _handle_dbapi_exception
    util.raise_(
  File "C:\Users\soju_\AppData\Local\Programs\Python\Python310\lib\site-packages\sqlalchemy\util\compat.py", line 208, in raise_
    raise exception
  File "C:\Users\soju_\AppData\Local\Programs\Python\Python310\lib\site-packages\sqlalchemy\engine\base.py", line 1819, in _execute_context
    self.dialect.do_execute(
  File "C:\Users\soju_\AppData\Local\Programs\Python\Python310\lib\site-packages\sqlalchemy\engine\default.py", line 732, in do_execute
    cursor.execute(statement, parameters)
  File "C:\Users\soju_\AppData\Local\Programs\Python\Python310\lib\site-packages\pymysql\cursors.py", line 148, in execute
    result = self._query(query)
  File "C:\Users\soju_\AppData\Local\Programs\Python\Python310\lib\site-packages\pymysql\cursors.py", line 310, in _query
    conn.query(q)
  File "C:\Users\soju_\AppData\Local\Programs\Python\Python310\lib\site-packages\pymysql\connections.py", line 548, in query
    self._affected_rows = self._read_query_result(unbuffered=unbuffered)
  File "C:\Users\soju_\AppData\Local\Programs\Python\Python310\lib\site-packages\pymysql\connections.py", line 775, in _read_query_result
    result.read()
  File "C:\Users\soju_\AppData\Local\Programs\Python\Python310\lib\site-packages\pymysql\connections.py", line 1156, in read
    first_packet = self.connection._read_packet()
  File "C:\Users\soju_\AppData\Local\Programs\Python\Python310\lib\site-packages\pymysql\connections.py", line 725, in _read_packet
    packet.raise_for_error()
  File "C:\Users\soju_\AppData\Local\Programs\Python\Python310\lib\site-packages\pymysql\protocol.py", line 221, in raise_for_error
    err.raise_mysql_exception(self._data)
  File "C:\Users\soju_\AppData\Local\Programs\Python\Python310\lib\site-packages\pymysql\err.py", line 143, in raise_mysql_exception
    raise errorclass(errno, errval)
sqlalchemy.exc.OperationalError: (pymysql.err.OperationalError) (1054, "Unknown column 'contents.created_at' in 'field list'")
[SQL: SELECT contents.id AS contents_id, contents.access AS contents_access, contents.level AS contents_level, contents.detail AS contents_detail, contents.media_type AS contents_media_type, contents.created_at AS contents_created_at 
FROM contents 
WHERE contents.access = %(access_1)s 
 LIMIT %(param_1)s]
[parameters: {'access_1': 'ehbp5uG9cX5L4ICbSwpbjFp9dlzd7roS', 'param_1': 1}]
(Background on this error at: https://sqlalche.me/e/14/e3q8)
[2022-07-28 16:24:17,693.693] ERROR [229444] - Exception in ASGI application
Traceback (most recent call last):
  File "C:\Users\soju_\AppData\Local\Programs\Python\Python310\lib\site-packages\uvicorn\protocols\http\httptools_impl.py", line 401, in run_asgi
    result = await app(self.scope, self.receive, self.send)
  File "C:\Users\soju_\AppData\Local\Programs\Python\Python310\lib\site-packages\uvicorn\middleware\proxy_headers.py", line 78, in __call__
    return await self.app(scope, receive, send)
  File "C:\Users\soju_\AppData\Local\Programs\Python\Python310\lib\site-packages\uvicorn\middleware\message_logger.py", line 86, in __call__
    raise exc from None
  File "C:\Users\soju_\AppData\Local\Programs\Python\Python310\lib\site-packages\uvicorn\middleware\message_logger.py", line 82, in __call__
    await self.app(scope, inner_receive, inner_send)
  File "C:\Users\soju_\AppData\Local\Programs\Python\Python310\lib\site-packages\fastapi\applications.py", line 269, in __call__
    await super().__call__(scope, receive, send)
  File "C:\Users\soju_\AppData\Local\Programs\Python\Python310\lib\site-packages\starlette\applications.py", line 124, in __call__
    await self.middleware_stack(scope, receive, send)
  File "C:\Users\soju_\AppData\Local\Programs\Python\Python310\lib\site-packages\starlette\middleware\errors.py", line 184, in __call__
    raise exc
  File "C:\Users\soju_\AppData\Local\Programs\Python\Python310\lib\site-packages\starlette\middleware\errors.py", line 162, in __call__
    await self.app(scope, receive, _send)
  File "C:\Users\soju_\AppData\Local\Programs\Python\Python310\lib\site-packages\starlette\middleware\base.py", line 68, in __call__
    response = await self.dispatch_func(request, call_next)
  File "Z:\pl\micro\cdn\.\middleware\internal_api.py", line 44, in dispatch
    return await next(req)
  File "C:\Users\soju_\AppData\Local\Programs\Python\Python310\lib\site-packages\starlette\middleware\base.py", line 46, in call_next
    raise app_exc
  File "C:\Users\soju_\AppData\Local\Programs\Python\Python310\lib\site-packages\starlette\middleware\base.py", line 36, in coro
    await self.app(scope, request.receive, send_stream.send)
  File "C:\Users\soju_\AppData\Local\Programs\Python\Python310\lib\site-packages\content_size_limit_asgi\middleware.py", line 56, in __call__
    await self.app(scope, wrapper, send)
  File "C:\Users\soju_\AppData\Local\Programs\Python\Python310\lib\site-packages\starlette\exceptions.py", line 93, in __call__
    raise exc
  File "C:\Users\soju_\AppData\Local\Programs\Python\Python310\lib\site-packages\starlette\exceptions.py", line 82, in __call__
    await self.app(scope, receive, sender)
  File "C:\Users\soju_\AppData\Local\Programs\Python\Python310\lib\site-packages\fastapi\middleware\asyncexitstack.py", line 21, in __call__
    raise e
  File "C:\Users\soju_\AppData\Local\Programs\Python\Python310\lib\site-packages\fastapi\middleware\asyncexitstack.py", line 18, in __call__
    await self.app(scope, receive, send)
  File "C:\Users\soju_\AppData\Local\Programs\Python\Python310\lib\site-packages\starlette\routing.py", line 670, in __call__
    await route.handle(scope, receive, send)
  File "C:\Users\soju_\AppData\Local\Programs\Python\Python310\lib\site-packages\starlette\routing.py", line 266, in handle
    await self.app(scope, receive, send)
  File "C:\Users\soju_\AppData\Local\Programs\Python\Python310\lib\site-packages\starlette\routing.py", line 65, in app
    response = await func(request)
  File "C:\Users\soju_\AppData\Local\Programs\Python\Python310\lib\site-packages\fastapi\routing.py", line 227, in app
    raw_response = await run_endpoint_function(
  File "C:\Users\soju_\AppData\Local\Programs\Python\Python310\lib\site-packages\fastapi\routing.py", line 160, in run_endpoint_function
    return await dependant.call(**values)
  File "Z:\pl\micro\cdn\.\routes\internal\cdn.py", line 69, in delete
    Content.file_delete(access)
  File "Z:\pl\micro\cdn\.\database\content.py", line 73, in file_delete
    os.remove(path_join(CDN_DIR, access))
FileNotFoundError: [WinError 2] The system cannot find the file specified: './cdn\\Bm9HpQpGHhjtcSPuqsKkTLm4Ah8jpyPg'
[2022-07-28 16:25:05,032.032] ERROR [179392] - Exception in ASGI application
Traceback (most recent call last):
  File "C:\Users\soju_\AppData\Local\Programs\Python\Python310\lib\site-packages\uvicorn\protocols\http\httptools_impl.py", line 401, in run_asgi
    result = await app(self.scope, self.receive, self.send)
  File "C:\Users\soju_\AppData\Local\Programs\Python\Python310\lib\site-packages\uvicorn\middleware\proxy_headers.py", line 78, in __call__
    return await self.app(scope, receive, send)
  File "C:\Users\soju_\AppData\Local\Programs\Python\Python310\lib\site-packages\uvicorn\middleware\message_logger.py", line 86, in __call__
    raise exc from None
  File "C:\Users\soju_\AppData\Local\Programs\Python\Python310\lib\site-packages\uvicorn\middleware\message_logger.py", line 82, in __call__
    await self.app(scope, inner_receive, inner_send)
  File "C:\Users\soju_\AppData\Local\Programs\Python\Python310\lib\site-packages\fastapi\applications.py", line 269, in __call__
    await super().__call__(scope, receive, send)
  File "C:\Users\soju_\AppData\Local\Programs\Python\Python310\lib\site-packages\starlette\applications.py", line 124, in __call__
    await self.middleware_stack(scope, receive, send)
  File "C:\Users\soju_\AppData\Local\Programs\Python\Python310\lib\site-packages\starlette\middleware\errors.py", line 184, in __call__
    raise exc
  File "C:\Users\soju_\AppData\Local\Programs\Python\Python310\lib\site-packages\starlette\middleware\errors.py", line 162, in __call__
    await self.app(scope, receive, _send)
  File "C:\Users\soju_\AppData\Local\Programs\Python\Python310\lib\site-packages\starlette\middleware\base.py", line 68, in __call__
    response = await self.dispatch_func(request, call_next)
  File "Z:\pl\micro\cdn\.\middleware\internal_api.py", line 44, in dispatch
    return await next(req)
  File "C:\Users\soju_\AppData\Local\Programs\Python\Python310\lib\site-packages\starlette\middleware\base.py", line 46, in call_next
    raise app_exc
  File "C:\Users\soju_\AppData\Local\Programs\Python\Python310\lib\site-packages\starlette\middleware\base.py", line 36, in coro
    await self.app(scope, request.receive, send_stream.send)
  File "C:\Users\soju_\AppData\Local\Programs\Python\Python310\lib\site-packages\content_size_limit_asgi\middleware.py", line 56, in __call__
    await self.app(scope, wrapper, send)
  File "C:\Users\soju_\AppData\Local\Programs\Python\Python310\lib\site-packages\starlette\exceptions.py", line 93, in __call__
    raise exc
  File "C:\Users\soju_\AppData\Local\Programs\Python\Python310\lib\site-packages\starlette\exceptions.py", line 82, in __call__
    await self.app(scope, receive, sender)
  File "C:\Users\soju_\AppData\Local\Programs\Python\Python310\lib\site-packages\fastapi\middleware\asyncexitstack.py", line 21, in __call__
    raise e
  File "C:\Users\soju_\AppData\Local\Programs\Python\Python310\lib\site-packages\fastapi\middleware\asyncexitstack.py", line 18, in __call__
    await self.app(scope, receive, send)
  File "C:\Users\soju_\AppData\Local\Programs\Python\Python310\lib\site-packages\starlette\routing.py", line 670, in __call__
    await route.handle(scope, receive, send)
  File "C:\Users\soju_\AppData\Local\Programs\Python\Python310\lib\site-packages\starlette\routing.py", line 266, in handle
    await self.app(scope, receive, send)
  File "C:\Users\soju_\AppData\Local\Programs\Python\Python310\lib\site-packages\starlette\routing.py", line 65, in app
    response = await func(request)
  File "C:\Users\soju_\AppData\Local\Programs\Python\Python310\lib\site-packages\fastapi\routing.py", line 227, in app
    raw_response = await run_endpoint_function(
  File "C:\Users\soju_\AppData\Local\Programs\Python\Python310\lib\site-packages\fastapi\routing.py", line 160, in run_endpoint_function
    return await dependant.call(**values)
  File "Z:\pl\micro\cdn\.\routes\internal\cdn.py", line 60, in delete
    if Content.file_delete(access) == None:
  File "Z:\pl\micro\cdn\.\database\content.py", line 73, in file_delete
    os.remove(path_join(CDN_DIR, access))
FileNotFoundError: [WinError 2] The system cannot find the file specified: '\\\\RaiDrive-soju_\\WebDAV\\pl\\micro\\cdn\\cdn\\Bm9HpQpGHhjtcSPuqsKkTLm4Ah8jpyPg'
